Workbook

Sheet Final BOM
B2: Assembly Name | C2: X
B3: Assembly # | C3: 1
B4: Assembly Revision | C4: 46122
B5: Date of Approval | C5: 46091
B6: Total Cost (€) | C6: =SUM(K15:K49) -> 364.01 | E6: * INC VAT, everything listed except Additional Items
B7: Total Cost per Unit (€) | C7: =SUM(J15:J49) -> 269.38121 | E7: * INC VAT, everything listed except Additional Items
B13: Item # | C13: Lay Des. | D13: Mfg. | E13: Mfg. Des. | F13: Mfg./Sup. Part # | G13: Link | H13: Qty | I13: Units | J13: Unit Cost (€) | K13: Cost INC VAT (€) | M13: Legend | N13: Des. | O13: Unit Cost (€) | P13: Cost INC VAT (€)
B14: Components | M14: Components | O14: =O15+O24+O31 -> 218.62857 | P14: =P15+P24+P31 -> 257.31
B15: 1 | C15: PLA (1 kg spool) | D15: Prusa | E15: Prusament PLA Jet Black 1kg (NFC) | F15: IDF: 17704|IDS: 3414 | G15: https://www.prusa3d.com/product/prusament-pla-jet-black-1kg-nfc/ | H15: 1 | I15: 0.64 | J15: =(K15/H15)*I15 -> 21.1136 | K15: 32.99 | N15: Vessel Bath Components | O15: =SUM(J15:J23) -> 47.40857 | P15: =SUM(K15:K23) -> 86.09
B16: 2 | C16: Eraser | D16: Milan | E16: Milan 4 Pack Synthetic Rubber Erasers Blister Card | F16: 420/0020 | G16: https://www.easons.com/milan-4-pack-synthetic-rubber-erasers-blister-card-4200020 | H16: 4 | I16: 4 | J16: =(K16/H16)*I16 -> 2.49 | K16: 2.49
B17: 3 | C17: Puck LED | D17: OSRAM | E17: OSRAM LED rechargeable furniture light DOT-IT, 1.8 cm, white touch dimmer | F17: 10044291 | G17: https://www.lights.ie/p/osram-led-rechargeable-furniture-light-dot-it-1-8-cm-white-touch-dimmer-10044291.html | H17: 1 | I17: 1 | J17: =(K17/H17)*I17 -> 9.9 | K17: 9.9
B18: 4 | C18: M3 40 mm Pan Head Bolt (0.5 mm pitch) | D18: McMaster-Carr | E18: Passivated 18-8 Stainless Steel Pan Head Phillips Screws | F18: 92000A136 | G18: https://www.mcmaster.com/92000A136/ | H18: 100 | I18: 27 | J18: =(K18/H18)*I18 -> 3.66201 | K18: 13.563
B19: 5 | C19: M3 12 mm Hex Socket Bolt | D19: McMaster-Carr | E19: Alloy Steel Socket Head Screw, Zinc Plated, M3 x 0.5 mm Thread, 12 mm Long | F19: 95263A146 | G19: https://www.mcmaster.com/95263A146/ | H19: 50 | I19: 24 | J19: =(K19/H19)*I19 -> 4.07616 | K19: 8.492
B20: 6 | C20: M4 Hex Nut (Full) | D20: McMaster-Carr | E20: Zinc-Plated Steel Hex Nut, Medium-Strength, ISO Class 8, M3 x 0.5 mm Thread Size | F20: 90591A250 | G20: https://www.mcmaster.com/90591A250/ | H20: 100 | I20: 52 | J20: =(K20/H20)*I20 -> 1.5158 | K20: 2.915
B21: 7 | C21: M3 Washer | D21: McMaster-Carr | E21: 18-8 Stainless Steel General Purpose Washer | F21: 93475A230 | G21: https://www.mcmaster.com/93475A230/ | H21: 100 | I21: 6 | J21: =(K21/H21)*I21 -> 0.2238 | K21: 3.73
B22: 8 | C22: Elastic Band Assortment | D22: Tiger | E22: Tiger Essential Rubber Bands Coloured - 100g | F22: 209/7818 | G22: https://www.easons.com/tiger-essential-rubber-bands-coloured-100g-2097818 | H22: 1 | I22: 1 | J22: =(K22/H22)*I22 -> 4 | K22: 4
B23: 9 | C23: Extension and Compression Spring | D23: RS | E23: Rolson 61298 150 pc Spring Assortment Hardware Pin, Silver | F23: B000QF7JTO | G23: https://www.amazon.ie/Rolson-61298-Spring-Assortment-Hardware/dp/B000QF7JTO/ref=sr_1_5?crid=29HLJ8JIOZSYI&dib=eyJ2IjoiMSJ9.5AA5BDT3Shk0fXWOu_DjRMVxJVVWB8sb_oJ9rbi5slo3wp1d2pS9tcdeuiTGLPccGCXMowBPZkpJi8Zd1z86VxRRgtpInBAsglgX_N1CT0h6CWsLYweTU8HwK_C_gqzP7hDXcTm59eqNLWe7oYawN7onafmm69v6s4xw6W9fe0LRCjNmP9YmARYiSD8DIowGbV42g9xZxsKnmoW2S_eK6WGkQE32gafTAQb-vm7G78FHwnp0OLQBUhoKNr5ytwaqGL8QSQ2_uh2wukTNhZX3LvtHEGE8QFWIzoQQODmP0P8.kslOjIac5-f-6W9F9bytFg67oYfKQrVRLt3FYS81ZOA&dib_tag=se&keywords=springs&qid=1774372649&sprefix=springs%2Caps%2C69&sr=8-5 | H23: 150 | I23: 8 | J23: =(K23/H23)*I23 -> 0.4272 | K23: 8.01
B24: 10 | C24: Microcontroller | D24: Arduino | E24: Arduino Uno REV3 | F24: A000066 | G24: https://www.amazon.ie/Arduino-Uno-REV3-A000066-Microcontroller/dp/B008GRTSV6/ref=sr_1_1?crid=OUSXCUWBYLWX&dib=eyJ2IjoiMSJ9.EP1e3hJTqCDPxSPSdzKsYXXK89oLGPYS3mPr8kqpi9m_m8sX2BnsTAzd5p0iGqjm0r5NwVDchvWiyzUg_op6hIqga4hiBQGYQfxF75v7W6ONafmS33w-nwMwmSW5DfR2voFKSKfb9obF3PAskJtliKHh1jE-enTl8M2BSNgmTlq0zQ6M2CnqDbV4rH-LrTKvbl-XGPaP_529iBgITkvjauwJctZU7UmboPIr8arvq7oXZscBffMn7Yg2P3dOXe7Rizcdxu_08_sndMW7rD_vYT0OOFhpAugLtRXdsroOT-w.gwfU48I-h0PDse4qU7B1TNRRiWcgZFl6OS8YD3uFxkM&dib_tag=se&keywords=arduino%2Buno%2Brev3&qid=1774373258&sprefix=arduino%2Buno%2Brev3%2Caps%2C449&sr=8-1&th=1 | H24: 1 | I24: 1 | J24: =(K24/H24)*I24 -> 28.85 | K24: 28.85 | N24: Pressure Components | O24: =SUM(J24:J30) -> 92.15 | P24: =SUM(K24:K30) -> 92.15
B25: 11 | C25: Breadboard | D25: Velleman | E25: Velleman VTBB3 High-Quality 400 Holes Breadboard, Multi-Colour | F25: VTBB3 | G25: https://www.amazon.ie/Velleman-VTBB3-High-Quality-Breadboard-Multi-Colour/dp/B077ZKDQKW/ref=sr_1_5?crid=6C0XMR1ZUG8C&dib=eyJ2IjoiMSJ9.IgQ8FrGD42aA5Y6jdL1F1wpnIF0qVaC_N0MinZ8ZZwZpvErRAzJFEcj9gF2AbYktTcLEUSE8zmFT6hWzQvhckdvvLeS5hDyZ86KdY12vD0L0b9H1I7GGuhh_RZRV1UwSqUkGppmLklKm6VgNd1Jkczht6TOJsEMS2fvU3c7QyNU2i7oh9w-4VMHUKUk4_vOOEV4Dv7O9GfT_4qNJfPoA3LrqYgm5tTZSueN8-tAmnZ-RFH3h69jCGA9sZSWlUoFGlS1WRJWLSIgzm_o3eCZ5Uz4uy8293jth9Ay9sBUGQjU.3C7F2y152isUI7ysooZTCvIQN48M3g7C6GBZ5rGGATM&dib_tag=se&keywords=breadboard&qid=1774373335&sprefix=breadboar%2Caps%2C74&sr=8-5 | H25: 1 | I25: 1 | J25: =(K25/H25)*I25 -> 3.49 | K25: 3.49
B26: 12 | C26: Peristaltic Pump | D26: DFRobot | E26: Gravity Digital Peristaltic Pump, for Arduino, Raspberry Pi & micro:bit Board | F26: DFR0523 | G26: https://ie.farnell.com/dfrobot/dfr0523/gravity-digital-peristaltic-pump/dp/3517940?CMP=KNC-GIE-GEN-SKU-OPTMYZR&mckv=s_dc%7Cpcrid%7C800683241016%7Ckword%7Cdfr0523%7Cmatch%7Cp%7Cplid%7C%7Cslid%7C%7Cproduct%7C%7Cpgrid%7C182670552432%7Cptaid%7Ckwd-531424226057%7C&gad_source=1&gad_campaignid=22770033025&gbraid=0AAAAAD8yeHkXzG0RDGa-h1lPLySOOWPET&gclid=Cj0KCQjw7IjOBhDyARIsAFzrWQyBoPorGJounL4TE3Uxk-v0Nbku6HIIPotZK0QO4eDuFTx49vfVbjgaAtJvEALw_wcB | H26: 2 | I26: 2 | J26: =(K26/H26)*I26 -> 23.72 | K26: 23.72
B27: 13 | C27: Jumper Wire Kit | D27: Haochen | E27: 560 PcsJumper Wire Kit | F27: B07FBCJ7GK | G27: https://www.amazon.ie/PcsJumper-Breadboard-Preformed-Solderless-Prototyping/dp/B07FBCJ7GK/ref=sr_1_7?crid=9V1JDZ8KUS4K&dib=eyJ2IjoiMSJ9.DO6s-fZ9KciFDvEaFYCvvNxCSO2r-dC0oBrBMkO2_JtuxoAeKBG3oDd9VnKIjAW0x8GIQ9t1Ba76YZVUpHRWg3k7-X_gRbgY8vanEAgzCB8mGBF_hyfeKPsMugk2-YBg-S9-jmjpX1itYyaaSzV4otuN-yzgxVPEhaZZSsZH769NT--6yEsJpZlM8NHWBCp6lLOfIn7tXYFn0Nkl3JkykJuNExOzdbAPB8Auk7OFgpdBRVH50f765L2qZ44VOFhoj-GeutdkYkglro32Mbri1xKDUgb755BQbgl_TRLYTXs.mAddw7Ea2FhyIESrMLCTclAjEWtolihLVFGIKHiKtUo&dib_tag=se&keywords=breadboard+jumper+wire+kit&qid=1774373610&sprefix=breadboard+jumper+wire+ki%2Caps%2C181&sr=8-7 | H27: 1 | I27: 1 | J27: =(K27/H27)*I27 -> 7.4 | K27: 7.4
B28: 14 | C28: Barrel Jack to Pin Adaptor | D28: DFRobot | E28: DC Power Connector, Jack, Screw | F28: FIT0151 | G28: https://ie.farnell.com/dfrobot/fit0151/dc-barrel-adapter-jack-5-5x2-1mm/dp/4308210?CMP=KNC-GIE-GEN-Shopping-Pmax-New&mckv=_dc%7Cpcrid%7C%7C&gad_source=1&gad_campaignid=22128113228&gbraid=0AAAAAD8yeHmb6XQ1Ooa6OtHWM_rfQxgK3&gclid=Cj0KCQjw7IjOBhDyARIsAFzrWQzUfCj7Szaap4B8m0tx_He-YntIbEx9kkgGDgefMjGx4QEPlQaGn-4aAvfhEALw_wcB | H28: 1 | I28: 1 | J28: =(K28/H28)*I28 -> 2.02 | K28: 2.02
B29: 15 | C29: Power Adapter | D29: Mean Well | E29: MEAN WELL 30W Power Brick AC/DC Adapter 5V dc Output, 6A Output | F29: GST60A05-P1J | G29: https://int.rsdelivers.com/product/mean-well/gst60a05-p1j/mean-well-30w-power-brick-ac/dc-adapter-5v-dc-output-6a-output/8808391 | H29: 1 | I29: 1 | J29: =(K29/H29)*I29 -> 23.73 | K29: 23.73
B30: 16 | C30: Power Cable | D30: Pro Elec | E30: LEAD UK PLUG TO IEC C13 BLACK 0.5M | F30: PELB1202 | G30: https://ie.farnell.com/pro-elec/pelb1202/lead-uk-plug-to-iec-c13-black/dp/4690705?CMP=KNC-GIE-GEN-Shopping-Pmax-New&mckv=_dc%7Cpcrid%7C%7C&gad_source=1&gad_campaignid=22128113228&gbraid=0AAAAAD8yeHmb6XQ1Ooa6OtHWM_rfQxgK3&gclid=Cj0KCQjw7IjOBhDyARIsAFzrWQz-qQ6VXk8Y7-ErCWc5Na8sC8z3WpYCE9PhtqMLGsSZaG3iYuss6HkaAtKqEALw_wcB | H30: 1 | I30: 1 | J30: =(K30/H30)*I30 -> 2.94 | K30: 2.94
B31: 35 | C31: Cooking Pot | D31: GSW | E31: GSW Stahlwaren Stock Pot with Glass Lid, Stainless Steel, Polished Finish, 5 Litre, 20x18cm, Silver/Clear | F31: 990189 | G31: https://www.amazon.ie/GSW-Stahlwaren-Stainless-Polished-20x18cm/dp/B01LXV1FI1/ref=sr_1_5?crid=2B7DYT9P8HSDV&dib=eyJ2IjoiMSJ9.OFETZkheDyLd5hFcG8Oz8CmpBewOb50FC_s8W-G6RceFTeXRIO3KCWIfrLiJa2DkbMD1qAPuBbxjP5AxFxR5WT6q7ht5L3pF8VYw-fYD_KdYIKDUdFKFTgKAHnDnj2f8nO57q3W8I7QZQebSR8iT75JZS6lZYwmOEySDe3n74vqKLHjGQkSqfo0AXgXYLQWpx0f9db3TvV1KN78EK3iOXCfDLTv6KDCbmhSgToyg5Ns.JiY9DvAc__fSLlbiR9jZcgx1daUmlwt20QwwTw0UwEo&dib_tag=se&keywords=cooking%2Bpot&qid=1774376255&s=home&sprefix=cooking%2Bpot%2Chome%2C69&sr=1-5&th=1 | H31: 1 | I31: 1 | J31: =(K31/H31)*I31 -> 21.99 | K31: 21.99 | N31: Temperature Components | O31: =SUM(J31:J33) -> 79.07 | P31: =SUM(K31:K33) -> 79.07
B32: 34 | C32: Immersion Circulator | D32: Wancle | E32: Wancle Sous Vide Sous Vide Machine Precision Cooker 1100W Sous Vide Cooker IPX7 Waterproof Immersion Circulator With Reservation Function Easy to Store (Black) | F32: M820 | G32: https://www.amazon.ie/Wancle-Precision-Waterproof-Circulator-Reservation/dp/B094921FYY?th=1 | H32: 1 | I32: 1 | J32: =(K32/H32)*I32 -> 52.09 | K32: 52.09
B33: 36 | C33: Thermometer | D33: Europapa | E33: EUROPAPA Digital Fever Thermometer for Babies, Children and Adults, Thermometer for Oral, Axillary or Rectal Use, Waterproof with Fever Alarm (Purple) | F33: 80189 | G33: https://www.amazon.ie/EUROPAPA-Thermometer-Children-Axillary-Waterproof/dp/B0CBP1F19R/ref=sr_1_2_sspa?crid=QPWHF76P3UDA&dib=eyJ2IjoiMSJ9.Z6VbW3vxoYhe_mLvzRrrK_QONFFVlLdcUYEqVzSW3pPf4wZoR0VDIxRJTbuDWej1u2RwRCMnns8BoDVXGRdGHQPeo9TRPFHgOh-9gR0RiUGeOvsTSVwCPx1zO-GZKgi5nNd5DAIsmdtKbUa5j6z48qt-bFLIuGffkcG9PRnMUi67qARiDSrACuSyvf52DT4ndgBBIbfqGaaVDgxSiR2vVivANmA46TeqKJK59lynQnDrtbwd4Rs6-W4wGv9R-F_faRWqVfPl5X4v8Z1T352utXIc15pF0rd1SKosaf8QkfY.NLPOezcSGwjlOAh1H86_p9MoKcHJiwn42jrYQNDRHok&dib_tag=se&keywords=digital%2Bthermometer&qid=1774377457&sprefix=digital%2Bthermo%2Caps%2C72&sr=8-2-spons&aref=6UbL6g3Mna&sp_csd=d2lkZ2V0TmFtZT1zcF9hdGY&th=1 | H33: 1 | I33: 1 | J33: =(K33/H33)*I33 -> 4.99 | K33: 4.99
B34: Consumables | M34: Consumables | O34: =O35+O40 -> 36.632643 | P34: =P35+P40 -> 92.58
B35: 17 | C35: Dispensing Tip (30 Gauge) | D35: Kahnetics | E35: Kahnetics Purple Straight Dispensing Tip, 30 Gauge | F35: KDS3012P | G35: https://ie.rs-online.com/web/p/dispensing-tips/4003902 | H35: 50 | I35: 2 | J35: =(K35/H35)*I35 -> 1.7884 | K35: 44.71 | N35: Construction Consumables | O35: =SUM(J35:J39) -> 11.482643 | P35: =SUM(K35:K39) -> 67.43
B36: 18 | C36: Leur Lock | D36: AIEX | E36: 30pcs Syringe Adapter, Clear Female Luer Lock 1/8" Luer Lock Connector Kit to Syringe Coupler Adapter (3.2mm) | F36: B13246 | G36: https://www.amazon.ie/Syringe-Adapter-Female-Connector-Coupler/dp/B0BMFJSJP1/ref=sr_1_7?adgrpid=184449477008&dib=eyJ2IjoiMSJ9.98YRqnMaglBZ_Mw7NOmXsSygVMX0K7RKxhWDrvrt42MZeQdiGg9FNBQGFTkg2BeIdste6ZojnMpM5Lms4c8J9yq6vVIq0Dr8LoEx4K92FS_bXD-cn5sis6ssJbRb1uKqBL0qrKIxkjnEBqv4TTNwfFCBJFtL2-mE2BaLAlwnIb4CdBoY3HUt7xrvycqUsfbywDCLvRgHtqBJZX2nbjhfwC7Ta3gRpic1Js0FQpL-mSeBCqbEppZ8hxsNdWomgumMJgPTt4hYvwCi6KnRm2FJCaqNRJGUEAWFV49B6qhGKsA.qLCaw07kewbq_Z-yvRY-XatkoStQyqtki5fCACnx2lE&dib_tag=se&gad_source=1&hvadid=749557497774&hvdev=c&hvlocphy=1007850&hvnetw=g&hvqmt=b&hvrand=4579167085094051697&hvtargid=kwd-299122711424&hydadcr=1913_2361712&keywords=luer+lock+connector&qid=1774377300&sr=8-7 | H36: 30 | I36: 2 | J36: =(K36/H36)*I36 -> 0.37533333 | K36: 5.63
B37: 19 | C37: Garden Wire | D37: Tenn Well | E37: 100m Green Garden Wire, Flexible Plant Wire Twist Ties with Cutter for Gardening Climbing Plants, Vines, Shrubs and Flowers | F37: B08ZC5G8V2 | G37: https://www.amazon.ie/tenn-well-Flexible-Gardening-Climbing/dp/B08ZC5G8V2/ref=sr_1_12?adgrpid=174819309733&dib=eyJ2IjoiMSJ9.JaDai8rkMg77Ihku6KORji7mLT5HpOgSFTPwdes53CjnEYaZOJ58DsGJohax-BwE4bATYZFNiHGx0mcYsE-mVjrsNE63W3IjM-1xnEMxZW5BGHDT93nIWIIezcLzMA52oQjqplkmSCMcMvyL-a7aonLLnEqDdjJlJQd48RGPHNPs4CzRKNabL8dP63IRkk6c7sZ5qkLlADlvJbaKPG0dSVwkPOrihPfLlpDwwIvwoexpfx2rne-ga-9z1l6mTGFPkrQDfiFBwjpbCrqtWftv8cCQuiszqX-gwOv3BcSkdyQ.wrXHdY_N3Lh9ymvdFj2MZe1_77b2b4FRVAIoFOcwoSw&dib_tag=se&gad_source=1&hvadid=739624586121&hvdev=c&hvlocphy=1007850&hvnetw=g&hvqmt=e&hvrand=12007122576768931918&hvtargid=kwd-296866735399&hydadcr=26439_2877180&keywords=garden%2Bwire&qid=1774374661&sr=8-12&th=1 | H37: 1 | I37: 1 | J37: =(K37/H37)*I37 -> 8.56 | K37: 8.56
B38: 20 | C38: Staple (no. 16 or 24/6) | D38: Q-Connect | E38: Q-Connect 24/6 Metal Precision Engineered Staples (1000 Pack) | F38: B002MXE9JQ | G38: https://www.amazon.ie/Q-Connect-Metal-Precision-Engineered-Staples/dp/B002MXE9JQ/ref=sr_1_5?adgrpid=175589183035&dib=eyJ2IjoiMSJ9.rWwb_jYclYuZojRFPNRZvCX8EkjucFM4ckvDqjgv56_ZGw5eVLfkkrb0lM5NxHeUcG22lsFsMhBmTiCYRDc4ViOAmh9XWwGJOthVWPBGwFuN0NYjSeJOcgB3HSkqtUOBSbfxSAUOJ_D3YMPcahBIrTrqkoZg7AfkIbbuYeql3olWo5v9D71WUn5Zb9m61s1yiayP2HRGL3U7Et9kuaZfiGhhMZAjJtJiDPoQs-joX9A2VdwthWVmHyqcnrCImjrkJ6YnTmndbly-lucNb2Hp1q5zGBiJxq3YOQ6b4Og7c94.zVtHgfUUM-shpxuWIL3XVKyyHPnlr0J-opHiEtuysCQ&dib_tag=se&gad_source=1&hvadid=739624557987&hvdev=c&hvlocphy=1007850&hvnetw=g&hvqmt=e&hvrand=374382684355706996&hvtargid=kwd-301533371703&hydadcr=28488_2545942&keywords=staples%2B24%2F6&qid=1774374831&sr=8-5&th=1 | H38: 1000 | I38: 3 | J38: =(K38/H38)*I38 -> 0.00291 | K38: 0.97
B39: 21 | C39: Petri Dish (60 mm D) | D39: Melgo | E39: 10 Pcs Plastic Petri Dish, Sterile Bacterial Culture Dish, Laboratory Plant Cell Tissue Petri Dish Accessories for Lab Supplies, School Science Equipment (Plastic-60mm-10Pcs) | F39: B0BB9RLV52 | G39: https://www.amazon.ie/Bacterial-Laboratory-Accessories-Equipment-Plastic-60mm-10Pcs/dp/B0BB9RLV52/ref=sr_1_3?crid=2K1F0JFUX1JHV&dib=eyJ2IjoiMSJ9.WTSV4OXRGm_wV1huKfRGJWbB-wonjDVcCTnB7lgobePc4wGKc8Qzv59xZo1Z3EbDStRd1b7GML55HcL1c7RWzGCkZ-FeiT2VCrUIBeMi8WTeVsUj_iZfYNH8wbyUgnsxc1HmkJnEUmXJMAqYTD1kvXw1e9y0PT2P9s4IUrc75KgjKCn5jwEydjF7yndEQjTyj3QCVrIDO9H_KI5lMApoAZmj1FZ_dM_YADs1qP2mKSgi2fCMv043JAHh4ZST-_OZ0TODmQUfYK4eM5vNvrdRAdOOd8NzY7elfFJenw7mNdI.8NOxx73mqYRFhcA0Mbi4mZVWP6Tf8ab-y7GzpKq9Mkc&dib_tag=se&keywords=petri%2Bdish%2B60%2Bmm&qid=1774375042&sprefix=petri%2Bdish%2B60%2Bmm%2Caps%2C55&sr=8-3&th=1 | H39: 10 | I39: 1 | J39: =(K39/H39)*I39 -> 0.756 | K39: 7.56
B40: 22 | C40: Thread | D40: Korbond | E40: Korbond CORE Mix Polyester Thread Selection by Korbond-12 x 32m spools – 10 Colours – 384 metres – Hand and Machine Sewing, Repairs, Crafting, White | F40: B007MCRA84 | G40: https://www.amazon.ie/Korbond-Polyester-Thread-Selection-Korbond-12/dp/B007MCRA84/ref=sr_1_5?adgrpid=174959828396&dib=eyJ2IjoiMSJ9.cGxskkPe8voLLT0zw6UGyFv0jcBjwGpnWgq13Kq7RJ-YP0z9ZLpEZ_5UkltLqCHdjvyPkxzGaG2sx_2RPzqZywQGUDKx6_61x9i3BSA9jRQGEEWB1l_S4rfmbOy-MI_2um0OanUwTzSGEoXhVK6aK2Bl-bVj7bF-zF8iLUlGoPOdGTqkK2auXT1_YPcAnKNR-dW79q5Nzz4sX-FsmKXEPTiWLLFv6bCdxpRffsb9lv6ACDoae13UVNBe6C6skzWILBLjNCb2f4LuPlRzEcapibyB-gyTUgd2syfwZo3povc.rczSj10VcIRr6up2jJMh4eFuo3BZsrUGSZLTpC9gyQs&dib_tag=se&gad_source=1&hvadid=739730272781&hvdev=c&hvlocphy=1007850&hvnetw=g&hvqmt=e&hvrand=10890328306146242116&hvtargid=kwd-39549230&hydadcr=5018_2454312&keywords=sewing%2Bthread&qid=1774375190&sr=8-5&th=1 | H40: 1 | I40: 1 | J40: =(K40/H40)*I40 -> 2.38 | K40: 2.38 | N40: Testing Consumables | O40: =SUM(J40:J45) -> 25.15 | P40: =SUM(K40:K45) -> 25.15
B41: 23 | C41: Silicone Lubricant | D41: PETEC | E41: PETEC Silicone spray, 500 ml, 70850 | F41: 70850 | G41: https://www.amazon.ie/PETEC-Silicone-spray-500-70850/dp/B018461HL2/ref=sr_1_4?adgrpid=173616327334&dib=eyJ2IjoiMSJ9.PBqsSN0GGB5PNz-J3BWDeQXWX69D8jhAuueIAOU6qoDwvVXiKdguWKTxZ7pq6RunxOYQGnDWowG63pjngNV5sf9u1Nmo6q7uHoxKYwEtxGlZW4ClULGzLYiHb8qwMBy90nTqMPWs4AkENol0kpxwMhMhxJWlcl02fC5vYlcUUQqHMmk67ZSsRpQt-HRhE91vhbEksGH6q03-TZrgy8EysIJkrNNp7dfO4iN4GPf1MdQ8QKzi-5bEs6C4BSYTwk8AX21-Blm2ZaPRm7O98YdfFsHiZ8I7sPr33QAgQOAI_n4.3zDh2COtf4UI4mfWfGsBX-d-ix_InjbyHULI2wMQHeY&dib_tag=se&gad_source=1&hvadid=739737594476&hvdev=c&hvlocphy=1007850&hvnetw=g&hvqmt=e&hvrand=4329585647599261949&hvtargid=kwd-253203967&hydadcr=15344_2417459&keywords=silicone+spray+lubricant&qid=1774375291&sr=8-4 | H41: 1 | I41: 1 | J41: =(K41/H41)*I41 -> 6.98 | K41: 6.98
B42: 24 | C42: Super Glue | D42: Loctite | E42: Loctite 950014 Superglue Gel | F42: 950014 | G42: https://www.amazon.ie/Loctite-2056169-950014-Superglue-Gel/dp/B00U1OPL8Q/ref=sr_1_5?crid=2NPRO5XODENME&dib=eyJ2IjoiMSJ9.aQRjr2nR49R9jHbJfiFpu2zH3L4CICTGnhTArv7cPdX6i2Wk3pQyfqClh2vo5oGt_Bq-hiZ24R2b8Yqeqytsd5SK3y5QI6b5xsnDBTPDX5rdpgZZKeVbS1WJvg5zH8v5Urpj1A9Tv2_V6BiPZr8g8V6qu9qKp3kgYF8WFA9Jco4uN-nZLZLA1SuavTF18wP7joYpLWydRJdXadw6xSLFgA3N3rdha20TFXRiZ6Esii8L-ZjKI5Rw9UR_NrEYcYXr4J0hEcOv878R7tX03ahNvmH5pBgldpnBxjxBEAGQaXo.ed65uxlgOnhnIujcIRkIHy3xL-OfuEWFtAJGT2LSQCg&dib_tag=se&keywords=Super+Glue&qid=1774375360&sprefix=super+glue%2Caps%2C63&sr=8-5 | H42: 1 | I42: 1 | J42: =(K42/H42)*I42 -> 4.49 | K42: 4.49
B43: 25 | C43: Hook and Loop Fastener | D43: Velcro | E43: VELCRO® Brand | Stick On Tape | Cut-to-Length Strong Hook & Loop Self Adhesive Sticky Tape Perfect for Room Décor & Home, Office, Garage Use | Black | 20mm x 1m | F43: N/A | G43: https://www.amazon.ie/VELCRO®-Brand-Length-Adhesive-Perfect/dp/B0017S83PI/ref=sr_1_5?crid=1F6Y7XWWSLYV5&dib=eyJ2IjoiMSJ9.9LylQbXg4FB4DEUEAWj0ePLA14NAT7bZh5QYnZ17TySBbBVPPvEvgTLCylSCVIYhGeHSoVNeEPo_kZfRlGzuAe_A7p7-Fq0BCDMR7ILHciWDO0tO44stUm6sH3U74M67X2Qnco9F0Q0av0BEqsv6gFqW86VaEG50I8UapMOMZFsYsD06bC0bFhdv7KCWXGR_GmaJ6jBCRNKP2SJhC_NtZ_UyTsbFC07gER7oNdV_0W7eV_r1Z2Z9_rLGflkHDAvhzVkmkz1uRMD22604lDwqY0Db2bQnou9NIrHeZ6BOBI8.6D5xbU-MTx3Xb-d133ahYiUbpBPzKNsS54aVfqukOF8&dib_tag=se&keywords=velcro&qid=1774378939&sprefix=velcro%2Caps%2C73&sr=8-5 | H43: 1 | I43: 1 | J43: =(K43/H43)*I43 -> 4.39 | K43: 4.39
B44: 26 | C44: Nail Polish Remover | D44: Cutex | E44: Cutex Nourishing Nail Polish Remover 200 ml | F44: 7240886000 | G44: https://www.amazon.ie/Cutex-Nourishing-Nail-Polish-Remover/dp/B06XB9Q6ZX/ref=sr_1_5?crid=1L92NABUBNFOI&dib=eyJ2IjoiMSJ9.4JHn-jOpvyST3kfTGMeonncqxvrlA81zgE8hvTgv312v4Ulf4OcVeNbc0vm3JKc_vchJx2aoP2qd8N1-MNVI2jda09dlx0V-Hl5M37a060ieZ08uLDzXizVoR3YWpZ85in-S73eXL6cbf63fsCZpkvSiySvAM4oaV47OONphNTy4sXSxOSrzEHHdw5s-FqD8SaQwLVeoVg4ULz6PdY9v2BUN1q5hdJ-UhwWbS4dN3CPQop3hJ6I5kaGLFvHoR94caY4I5hvU0B6tBREzLhhcLLKkIpU_ZsLa7hYIAG5ruog.ZGmx_eqINCgiZVOmZzBpsAKsjSoGAL81kH4ZraatVAc&dib_tag=se&keywords=Nail+Polish+Remover&qid=1774375412&sprefix=nail+polish+remover%2Caps%2C89&sr=8-5 | H44: 1 | I44: 1 | J44: =(K44/H44)*I44 -> 2.99 | K44: 2.99
B45: 27 | C45: Adhesiive Putty | D45: Bostik | E45: BOSTIK Blu Tack Light Blue - Permanent Plastic Reusable Adhesive, Reliable and Removable Fixation, 46 g | F45: ‎5048700002 | G45: https://www.amazon.ie/BOSTIK-Blu-Tack-Light-Blue/dp/B0015M12G8/ref=sr_1_2?crid=1BSTABELVX55M&dib=eyJ2IjoiMSJ9.fEidfBGQR9Hg2xFyTgmj4jjW4pC5-GgrFhqZpa5gm5b0Fta7h71spKT5Q8PB3rCMDuof_tvjl_9AIXcIyJ_ZB0e2KkkTpjShActrs07sAj8Llz8FhotE6tFtDO2N-CIloZ2otqeRY_B19ilcz50Tw5ftdNMMyST-GFziLtw1vKdUWmPv--fOG5HGpNdebDWfbBajV1lkED4YCB4Uj5dZGnJZVVY9MDklOYmeqkGouZ4283astohoANB6himqLDMOqvXT5mjqw6JPeDzBVZkKMu3XvU6pqz5nrrp-h7kKzM0.M4hyMd7CWWDNNj3JFJPZDjjuwumILO5P3ol9h_dUb6Y&dib_tag=se&keywords=blue+tac&qid=1774375512&sprefix=blue+tac%2Caps%2C64&sr=8-2 | H45: 1 | I45: 1 | J45: =(K45/H45)*I45 -> 3.92 | K45: 3.92
B46: Equipment | M46: Equipment | O46: =O47+O49 -> 14.12 | P46: =P47+P49 -> 14.12
...

Sheet Analysis
C4: Prototype (Unit) | D4: Prototype (Total)
B5: ='Final BOM'!N15 -> Vessel Bath Components | C5: ='Final BOM'!O15 -> 47.40857 | D5: ='Final BOM'!P15 -> 86.09
B6: ='Final BOM'!N24 -> Pressure Components | C6: ='Final BOM'!O24 -> 92.15 | D6: ='Final BOM'!P24 -> 92.15
B7: Temperature Components | C7: ='Final BOM'!O31 -> 79.07 | D7: ='Final BOM'!P31 -> 79.07
B8: ='Final BOM'!N35 -> Construction Consumables | C8: ='Final BOM'!O35 -> 11.482643 | D8: ='Final BOM'!P35 -> 67.43
B9: ='Final BOM'!N40 -> Testing Consumables | C9: ='Final BOM'!O40 -> 25.15 | D9: ='Final BOM'!P40 -> 25.15
B10: ='Final BOM'!N47 -> Construction Tools | C10: ='Final BOM'!O47 -> 8.16 | D10: ='Final BOM'!P47 -> 8.16
B11: ='Final BOM'!N49 -> Testing Tool | C11: ='Final BOM'!O49 -> 5.96 | D11: ='Final BOM'!P49 -> 5.96
C20: Prototype (Unit) | D20: Prototype (Total) | E20: HemoLens (Unit) | F20: HemoLens (Total) | G20: VasoTracker 1 (Unit) | H20: VasoTracker 2 (Unit) | I20: MDE IS-05 Wire Myograph (Unit) | J20: LSI 2-Channel Self-Heated Wire Myograph Package (Unit) | K20: DMT Pressure Myograph System - 112PP (Unit)
B21: ='Final BOM'!M14 -> Components | C21: ='Final BOM'!O14 -> 218.62857 | D21: ='Final BOM'!P14 -> 257.31 | E21: 642.35 | F21: 767.5 | G21: 1676.27 | H21: 4501.64 | I21: 9560 | J21: 17184.73 | K21: 45850
B22: ='Final BOM'!M34 -> Consumables | C22: 36.632643 | D22: 92.58 | E22: 2.64 | F22: 65.88 | G22: 0 | H22: 163.93 | I22: 0 | J22: 0 | K22: 0
B23: ='Final BOM'!M46 -> Equipment | C23: 14.12 | D23: 14.12 | E23: 0 | F23: 0 | G23: 0 | H23: 0 | I23: 0 | J23: 0 | K23: 0
B24: Total | C24: =SUM(C21:C23) -> 269.38121 | D24: =SUM(D21:D23) -> 364.01 | E24: =SUM(E21:E23) -> 644.99 | F24: =SUM(F21:F23) -> 833.38 | G24: =SUM(G21:G23) -> 1676.27 | H24: =SUM(H21:H23) -> 4665.57 | I24: =SUM(I21:I23) -> 9560 | J24: =SUM(J21:J23) -> 17184.73 | K24: =SUM(K21:K23) -> 45850
